Workbook
Name Slicer_Fiscal_Quarter: #N/A
Name Slicer_Region: #N/A

Sheet Business_Case
A1: MICROSOFT CORPORATION: REGIONAL & SEGMENT PERFORMANCE ANALYSIS (FY24–FY25)
A3: Course
A4: SADM | Group Assignment | Total Marks: 15
A7: Background
A8: Microsoft Corporation operates through three major business segments: Productivity and Business Processes, Intelligent Cloud, and More Personal Computing. It serves three customer groups Enterprise, Small and Medium Businesses (SMBs), and Consumers across five global regions: North America, Europe, Asia Pacific, Latin America, and the Middle East & Africa. Every quarter, Microsoft's regional and product teams report key business metrics such as units sold, revenue, operating cost, and customer satisfaction. Managers use this data to monitor business performance, compare regions and product segments, identify unusual patterns, and make informed business decisions.
A10: Your Role
A11: You are a Business Analyst Intern in Microsoft's Corporate Strategy team. The Head of Strategy has asked you to analyze the last two fiscal years of quarterly sales performance data (FY24–FY25) and present data-backed recommendations for the FY26 planning cycle.
A13: Business Problem
A14: Senior management wants to know: (1) which regions and segments are driving profitable growth, (2) wWhere high operating costs are reducing profits, (3) which product lines and customer types deserve more investment, and (4) where customer satisfaction is slipping and needs corrective action. Your analysis, built entirely in Excel, will directly inform these decisions.
A16: The Dataset
A17: The 'Dataset' sheet contains 240 simulated transaction-level records for FY24–FY25, with 10 variables covering time (Fiscal Quarter), geography (Region), business structure (Business Segment, Product Line, Customer Type), and performance (Units Sold, Revenue, Operating Cost, Customer Satisfaction Score). Figures are simulated for academic use and do not represent Microsoft's actual reported financials.
A19: What You Must Do
A20: Use Excel's analytical toolkit — Sorting, Filtering, PivotTables, PivotCharts, Descriptive Statistics, the Data Analysis ToolPak (Hypothesis Testing, Correlation, Regression), and a one-page interactive dashboard — to complete the 11 deliverables listed on the 'Questions' sheet.

Sheet Dataset
A2: Record_ID | B2: Fiscal_Quarter | C2: Region | D2: Business_Segment | E2: Product_Line | F2: Customer_Type | G2: Units_Sold | H2: Revenue_USD_Million | I2: Operating_Cost_USD_Million | J2: Customer_Satisfaction_Score | K2: Profit
A3: 1001 | B3: Q1 FY24 | C3: North America | D3: Productivity and Business Processes | E3: LinkedIn | F3: Enterprise | G3: 6285 | H3: 17.38 | I3: 10.09 | J3: 8.6 | K3: =H3-I3 -> 7.29
A4: 1002 | B4: Q1 FY24 | C4: North America | D4: Productivity and Business Processes | E4: Office 365 | F4: Enterprise | G4: 5225 | H4: 10.21 | I4: 6.33 | J4: 8.1 | K4: =H4-I4 -> 3.88
A5: 1003 | B5: Q1 FY24 | C5: North America | D5: Intelligent Cloud | E5: Windows Server | F5: SMB | G5: 2627 | H5: 16.59 | I5: 8.33 | J5: 8.8 | K5: =H5-I5 -> 8.26
A6: 1004 | B6: Q1 FY24 | C6: North America | D6: Intelligent Cloud | E6: Azure | F6: SMB | G6: 3468 | H6: 14.3 | I6: 8.59 | J6: 6.3 | K6: =H6-I6 -> 5.71
A7: 1005 | B7: Q1 FY24 | C7: North America | D7: More Personal Computing | E7: Windows | F7: SMB | G7: 5318 | H7: 11.76 | I7: 8.36 | J7: 9.4 | K7: =H7-I7 -> 3.4
A8: 1006 | B8: Q1 FY24 | C8: North America | D8: More Personal Computing | E8: Surface | F8: SMB | G8: 1633 | H8: 1.82 | I8: 1.48 | J8: 7.3 | K8: =H8-I8 -> 0.34
A9: 1007 | B9: Q1 FY24 | C9: Europe | D9: Productivity and Business Processes | E9: Office 365 | F9: Enterprise | G9: 4662 | H9: 26.04 | I9: 21 | J9: 9 | K9: =H9-I9 -> 5.04
A10: 1008 | B10: Q1 FY24 | C10: Europe | D10: Productivity and Business Processes | E10: LinkedIn | F10: SMB | G10: 2470 | H10: 10.92 | I10: 7.22 | J10: 6.7 | K10: =H10-I10 -> 3.7
A11: 1009 | B11: Q1 FY24 | C11: Europe | D11: Intelligent Cloud | E11: GitHub | F11: Enterprise | G11: 3935 | H11: 16.5 | I11: 9.59 | J11: 9.2 | K11: =H11-I11 -> 6.91
A12: 1010 | B12: Q1 FY24 | C12: Europe | D12: Intelligent Cloud | E12: Azure | F12: Enterprise | G12: 4795 | H12: 36.5 | I12: 20.76 | J12: 6.1 | K12: =H12-I12 -> 15.74
A13: 1011 | B13: Q1 FY24 | C13: Europe | D13: More Personal Computing | E13: Surface | F13: SMB | G13: 1258 | H13: -2.97 | I13: 2.27 | J13: 6.7 | K13: =H13-I13 -> -5.24
A14: 1012 | B14: Q1 FY24 | C14: Europe | D14: More Personal Computing | E14: Xbox | F14: SMB | H14: 7.26 | I14: 4.57 | J14: 6.9 | K14: =H14-I14 -> 2.69
A15: 1013 | B15: Q1 FY24 | C15: Asia Pacific | D15: Productivity and Business Processes | E15: LinkedIn | F15: SMB | G15: 5468 | H15: 18.57 | I15: 15.77 | J15: 7.8 | K15: =H15-I15 -> 2.8
A16: 1014 | B16: Q1 FY24 | C16: Asia Pacific | D16: Productivity and Business Processes | E16: Dynamics 365 | F16: Enterprise | G16: 4730 | H16: 23.96 | J16: 8.4 | K16: =H16-I16 -> 23.96
A17: 1015 | B17: Q1 FY24 | C17: Asia Pacific | D17: Intelligent Cloud | E17: Windows Server | F17: SMB | G17: 2784 | H17: 22.35 | I17: 17.69 | J17: 9 | K17: =H17-I17 -> 4.66
A18: 1016 | B18: Q1 FY24 | C18: Asia Pacific | D18: Intelligent Cloud | E18: Azure | F18: Enterprise | G18: 4337 | H18: 16.69 | I18: 12.1 | J18: 8.7 | K18: =H18-I18 -> 4.59
A19: 1017 | B19: Q1 FY24 | C19: Asia Pacific | D19: More Personal Computing | E19: Surface | F19: SMB | G19: 3060 | H19: 4.7 | I19: 3.82 | J19: 6.9 | K19: =H19-I19 -> 0.88
A20: 1018 | B20: Q1 FY24 | C20: Asia Pacific | D20: More Personal Computing | E20: Windows | F20: Consumer | G20: 3439 | H20: 2.51 | I20: 2.01 | J20: 7.8 | K20: =H20-I20 -> 0.5
A21: 1019 | B21: Q1 FY24 | C21: Latin America | D21: Productivity and Business Processes | E21: Office 365 | F21: SMB | G21: 3097 | H21: 13.59 | I21: 9.64 | J21: 6 | K21: =H21-I21 -> 3.95
A22: 1020 | B22: Q1 FY24 | C22: Latin America | D22: Productivity and Business Processes | E22: LinkedIn | F22: SMB | G22: 2171 | H22: 5.17 | I22: 4.37 | J22: 8.8 | K22: =H22-I22 -> 0.8
A23: 1021 | B23: Q1 FY24 | C23: Latin America | D23: Intelligent Cloud | E23: Azure | F23: Enterprise | G23: 3487 | H23: 24.74 | I23: 15.98 | J23: 6.2 | K23: =H23-I23 -> 8.76
A24: 1022 | B24: Q1 FY24 | C24: Latin America | D24: Intelligent Cloud | E24: Windows Server | F24: Enterprise | G24: 953 | H24: 5.17 | I24: 3 | J24: 9.1 | K24: =H24-I24 -> 2.17
A25: 1023 | B25: Q1 FY24 | C25: Latin America | D25: More Personal Computing | E25: Surface | F25: Consumer | G25: 2929 | H25: 3.93 | I25: 2.6 | J25: 9.1 | K25: =H25-I25 -> 1.33
A26: 1024 | B26: Q1 FY24 | C26: Latin America | D26: More Personal Computing | E26: Windows | F26: SMB | G26: 928 | H26: 0.85 | I26: 0.62 | J26: 6.8 | K26: =H26-I26 -> 0.23
A27: 1025 | B27: Q1 FY24 | C27: Middle East & Africa | D27: Productivity and Business Processes | E27: Office 365 | F27: Enterprise | G27: 2464 | H27: 5.03 | I27: 2.81 | J27: 6.8 | K27: =H27-I27 -> 2.22
A28: 1026 | B28: Q1 FY24 | C28: Middle East & Africa | D28: Productivity and Business Processes | E28: LinkedIn | F28: Enterprise | G28: 1236 | H28: 4.91 | I28: 3.77 | J28: 8.7 | K28: =H28-I28 -> 1.14
... A37: 1035 | B37: Q2 FY24 | C37: North America | D37: More Personal Computing | E37: Xbox | F37: Consumer | G37: 1482 | H37: 2.33 | I37: 1.65 | J37: 6.2 | K37: =H37-I37 -> 0.68
A38: 1036 | B38: Q2 FY24 | C38: North America | D38: More Personal Computing | E38: Surface | F38: Consumer | G38: 7303 | I38: 3.44 | J38: 7.4 | K38: =H38-I38 -> -3.44
A39: 1037 | B39: Q2 FY24 | C39: Europe | D39: Productivity and Business Processes | E39: LinkedIn | F39: Enterprise | G39: 4577 | H39: 17.11 | I39: 12.09 | J39: 9.3 | K39: =H39-I39 -> 5.02
A40: 1038 | B40: Q2 FY24 | C40: Europe | D40: Productivity and Business Processes | E40: Office 365 | F40: Enterprise | G40: 4875 | H40: 15.13 | I40: 8.92 | J40: 8.3 | K40: =H40-I40 -> 6.21
A41: 1040 | B41: Q2 FY24 | C41: Europe | D41: Intelligent Cloud | E41: Windows Server | F41: SMB | G41: 1694 | H41: 7.34 | I41: 4.21 | J41: 7 | K41: =H41-I41 -> 3.13
A42: 1041 | B42: Q2 FY24 | C42: Europe | D42: More Personal Computing | E42: Surface | F42: Consumer | G42: 4864 | H42: 8.5 | I42: 4.94 | J42: 9.1 | K42: =H42-I42 -> 3.56
A43: 1042 | B43: Q2 FY24 | C43: Europe | D43: More Personal Computing | E43: Xbox | F43: SMB | G43: 1594 | H43: 1.15 | I43: 0.73 | J43: 8.1 | K43: =H43-I43 -> 0.42
A44: 1043 | B44: Q2 FY24 | C44: Asia Pacific | D44: Productivity and Business Processes | E44: LinkedIn | F44: Enterprise | G44: 4528 | H44: 24.53 | I44: 15.34 | J44: 9.2 | K44: =H44-I44 -> 9.19
A45: 1044 | B45: Q2 FY24 | C45: Asia Pacific | D45: Productivity and Business Processes | E45: Dynamics 365 | F45: Enterprise | G45: 1324 | H45: 4.67 | I45: 2.57 | J45: 8.7 | K45: =H45-I45 -> 2.1
A46: 1045 | B46: Q2 FY24 | C46: Asia Pacific | D46: Intelligent Cloud | E46: Windows Server | F46: Enterprise | G46: 4817 | H46: 27.34 | I46: 13.75 | J46: 6.3 | K46: =H46-I46 -> 13.59
A47: 1046 | B47: Q2 FY24 | C47: Asia Pacific | D47: Intelligent Cloud | E47: GitHub | F47: Enterprise | G47: 3764 | H47: 27.44 | I47: 14.94 | J47: 6.4 | K47: =H47-I47 -> 12.5
A48: 1047 | B48: Q2 FY24 | C48: Asia Pacific | D48: More Personal Computing | E48: Surface | F48: Consumer | G48: 5666 | H48: 4.95 | I48: 2.88 | J48: 8.7 | K48: =H48-I48 -> 2.07
A49: 1048 | B49: Q2 FY24 | C49: Asia Pacific | D49: More Personal Computing | E49: Xbox | F49: SMB | G49: 6069 | H49: 13.16 | I49: 8.17 | J49: 6.6 | K49: =H49-I49 -> 4.99
...

Sheet Questions
B1: GROUP PROJECT DELIVERABLES
B2: DELIVERABLE 1 — Dashboard
A3: 1 | B3: Build a one-page interactive dashboard with KPI cards for Total Revenue, Total Units Sold, Total Operating Cost, and Profit (Revenue − Operating Cost). Which fiscal quarter had the highest profit, and which had the lowest?
A4: 2 | B4: Show a trend chart of Revenue by Fiscal Quarter (FY24 vs FY25) on your dashboard. Is Microsoft's revenue growing, declining, or flat overall, and what does the pattern suggest for FY26 planning?
A5: 3 | B5: Compare Revenue across the five Regions on your dashboard (chart or PivotTable). Which region is the strongest performer and which is the weakest, and what should management do about the weakest region?
A6: 4 | B6: Compare performance across Business Segments and Product Lines on your dashboard. Which segment or product line deserves more investment in FY26, and which is underperforming?
A7: 5 | B7: Compare average Customer Satisfaction Score across Customer Types and Regions on your dashboard. Where is customer satisfaction weakest, and what corrective action is most urgently needed?
B9: DELIVERABLE 2 — Hypothesis Testing
A10: 6 | B10: Microsoft's regional leadership believes that Enterprise customers report similarly satisfied levels no matter which region serves them, so no single region needs special attention. Frame this as a proper hypothesis (state H₀ and H₁), choose the correct statistical test to check this belief using the Customer Satisfaction Score for Enterprise customers across all five Regions, and test it at the 5% significance level. Report the test statistic, decision, conclusion, and what you would tell management — does the belief hold, and if not, which region(s) are pulling the average down?
B12: DELIVERABLE 3 — Correlation
A13: 7 | B13: For the business question “What factors drive Microsoft's Revenue?”, Plot and identify the dependent (Y) variable and at least two independent (X) variable candidates from the dataset, and justify your choice in one line.
A14: 8 | B14: Calculate the correlation coefficient between (a) Units Sold and Revenue, and (b) Operating Cost and Revenue. Which relationship is stronger, and what does that tell management about what really drives revenue?
A15: 9 | B15: Plot a scatter chart of Revenue (Y-axis) vs Units Sold (X-axis) on your dashboard or in Excel. Does the visual pattern match the correlation value from Deliverable 8? What does the shape of the scatter plot suggest for Microsoft's sales strategy?
B17: DELIVERABLE 4 — Linear Regression
A18: 10 | B18: Frame the business question, then run a linear regression of Revenue (Y) on Units Sold (X). Report the regression equation, R², coefficients. Use the equation to predict Revenue for a given Units Sold value (e.g., 5,000 units), and explain the managerial implication of this prediction.
A19: 11 | B19: Run a linear regression of Revenue (Y) on Customer Satisfaction Score (X). Report the regression equation, R², coefficients. Use the equation to estimate the Revenue impact if satisfaction improves by 1 point, and explain what this means for investing in customer experience.

Sheet Pivot
A3: Row Labels | B3: Sum of Revenue_USD_Million
A4: Q1 FY24 | B4: 350.15
A5: Q2 FY24 | B5: 308.81
A6: Q3 FY24 | B6: 345.93
A7: Q4 FY24 | B7: 384.41
A8: Q1 FY25 | B8: 476.91
A9: Q2 FY25 | B9: 412.15
A10: Q3 FY25 | B10: 424.61
A11: Q4 FY25 | B11: 437.5
A12: Grand Total | B12: 3140.47
A19: Row Labels | B19: Sum of Revenue_USD_Million
A20: Asia Pacific | B20: 755.23
A21: Europe | B21: 683.79
A22: Latin America | B22: 440.2
A23: Middle East & Africa | B23: 367.41
A24: North America | B24: 893.84
A25: Grand Total | B25: 3140.47
A35: Row Labels | B35: Sum of Profit
A36: Intelligent Cloud | B36: 630.07
A37: More Personal Computing | B37: 108.01
A38: Productivity and Business Processes | B38: 360.78
A39: Grand Total | B39: 1098.86
A42: Average of Customer_Satisfaction_Score | B42: Column Labels
A43: Row Labels | B43: Consumer | C43: Enterprise | D43: SMB | E43: Grand Total
A44: Asia Pacific | B44: 7.45 | C44: 7.65 | D44: 7.8 | E44: 7.6916667
A45: Europe | B45: 8.35 | C45: 7.9411765 | D45: 7.4125 | E45: 7.7234043
A46: Latin America | B46: 7.82 | C46: 8.05625 | D46: 7.6409091 | E46: 7.8166667
A47: Middle East & Africa | B47: 7.4142857 | C47: 7.6 | D47: 7.1961538 | E47: 7.3541667
A48: North America | B48: 7.15 | C48: 7.9625 | D48: 7.8653846 | E48: 7.8083333
A49: Grand Total | B49: 7.6405405 | C49: 7.84625 | D49: 7.5803279 | E49: 7.6786611
A53: Row Labels | B53: Sum of Revenue_USD_Million | C53: Sum of Operating_Cost_USD_Million
A54: Q1 FY24 | B54: 350.15 | C54: 206.88
A55: Q2 FY24 | B55: 308.81 | C55: 177.39
A56: Q3 FY24 | B56: 345.93 | C56: 233.08
A57: Q4 FY24 | B57: 384.41 | C57: 260.99
A58: Q1 FY25 | B58: 476.91 | C58: 320.78
A59: Q2 FY25 | B59: 412.15 | C59: 266.15
A60: Q3 FY25 | B60: 424.61 | C60: 283.29
A61: Q4 FY25 | B61: 437.5 | C61: 293.05
A62: Grand Total | B62: 3140.47 | C62: 2041.61
...

Sheet Deliverable 1 -Dashboard

Sheet Deliverable 2
A1: Deliverable 2 - Hypothesis Testing | H1: Working (simple calculation)
A3: Business question | B3: Do Enterprise customers have similar satisfaction across regions? | H3: Region | I3: Score | J3: Difference | K3: Difference²
A4: H0 | B4: Average satisfaction is the same across all five regions. | H4: =[1]Dataset!C16 -> Asia Pacific | I4: =Dataset!J16 -> 8.4 | J4: =I4-$C$16 -> 0.55375 | K4: =J4^2 -> 0.30663906
A5: H1 | B5: At least one region has a different average satisfaction. | H5: =[1]Dataset!C18 -> Asia Pacific | I5: =Dataset!J17 -> 9 | J5: =I5-$C$16 -> 1.15375 | K5: =J5^2 -> 1.3311391
A6: Test | B6: One-way ANOVA at 5% significance level. | H6: =[1]Dataset!C44 -> Asia Pacific | I6: =Dataset!J18 -> 8.7 | J6: =I6-$C$16 -> 0.85375 | K6: =J6^2 -> 0.72888906
H7: =[1]Dataset!C45 -> Asia Pacific | I7: =Dataset!J19 -> 6.9 | J7: =I7-$C$16 -> -0.94625 | K7: =J7^2 -> 0.89538906
A8: Enterprise satisfaction by region | H8: =[1]Dataset!C46 -> Asia Pacific | I8: =Dataset!J20 -> 7.8 | J8: =I8-$C$16 -> -0.04625 | K8: =J8^2 -> 0.0021390625
A9: Region | B9: Responses | C9: Average score | H9: =[1]Dataset!C47 -> Asia Pacific | I9: =Dataset!J21 -> 6 | J9: =I9-$C$16 -> -1.84625 | K9: =J9^2 -> 3.4086391
A10: Asia Pacific | B10: =COUNTIFS(Dataset!$C$3:$C$241,A10,Dataset!$F$3:$F$241,"Enterprise") -> 16 | C10: =AVERAGEIFS([1]Dataset!$J$3:$J$241,[1]Dataset!$C$3:$C$241,A10,[1]Dataset!$F$3:$F$241,"Enterprise") -> 7.65 | H10: =[1]Dataset!C76 -> Asia Pacific | I10: =Dataset!J22 -> 8.8 | J10: =I10-$C$16 -> 0.95375 | K10: =J10^2 -> 0.90963906
A11: Europe | B11: =COUNTIFS(Dataset!$C$3:$C$241,A11,Dataset!$F$3:$F$241,"Enterprise") -> 17 | C11: =AVERAGEIFS([1]Dataset!$J$3:$J$241,[1]Dataset!$C$3:$C$241,A11,[1]Dataset!$F$3:$F$241,"Enterprise") -> 7.9411765 | H11: =[1]Dataset!C77 -> Asia Pacific | I11: =Dataset!J23 -> 6.2 | J11: =I11-$C$16 -> -1.64625 | K11: =J11^2 -> 2.7101391
A12: Latin America | B12: =COUNTIFS(Dataset!$C$3:$C$241,A12,Dataset!$F$3:$F$241,"Enterprise") -> 16 | C12: =AVERAGEIFS([1]Dataset!$J$3:$J$241,[1]Dataset!$C$3:$C$241,A12,[1]Dataset!$F$3:$F$241,"Enterprise") -> 8.05625 | H12: =[1]Dataset!C105 -> Asia Pacific | I12: =Dataset!J24 -> 9.1 | J12: =I12-$C$16 -> 1.25375 | K12: =J12^2 -> 1.5718891
A13: Middle East & Africa | B13: =COUNTIFS(Dataset!$C$3:$C$241,A13,Dataset!$F$3:$F$241,"Enterprise") -> 15 | C13: =AVERAGEIFS([1]Dataset!$J$3:$J$241,[1]Dataset!$C$3:$C$241,A13,[1]Dataset!$F$3:$F$241,"Enterprise") -> 7.6 | H13: =[1]Dataset!C134 -> Asia Pacific | I13: =Dataset!J25 -> 9.1 | J13: =I13-$C$16 -> 1.25375 | K13: =J13^2 -> 1.5718891
A14: North America | B14: =COUNTIFS(Dataset!$C$3:$C$241,A14,Dataset!$F$3:$F$241,"Enterprise") -> 16 | C14: =AVERAGEIFS([1]Dataset!$J$3:$J$241,[1]Dataset!$C$3:$C$241,A14,[1]Dataset!$F$3:$F$241,"Enterprise") -> 7.9625 | H14: =[1]Dataset!C164 -> Asia Pacific | I14: =Dataset!J26 -> 6.8 | J14: =I14-$C$16 -> -1.04625 | K14: =J14^2 -> 1.0946391
H15: =[1]Dataset!C167 -> Asia Pacific | I15: =Dataset!J27 -> 6.8 | J15: =I15-$C$16 -> -1.04625 | K15: =J15^2 -> 1.0946391
A16: Overall Enterprise average | B16: =SUM(B10:B14) -> 80 | C16: =SUMPRODUCT(B10:B14,C10:C14)/B16 -> 7.84625 | H16: =[1]Dataset!C195 -> Asia Pacific | I16: =Dataset!J28 -> 8.7 | J16: =I16-$C$16 -> 0.85375 | K16: =J16^2 -> 0.72888906
H17: =[1]Dataset!C197 -> Asia Pacific | I17: =Dataset!J29 -> 7.1 | J17: =I17-$C$16 -> -0.74625 | K17: =J17^2 -> 0.55688906
A18: ANOVA summary | H18: =[1]Dataset!C224 -> Asia Pacific | I18: =Dataset!J30 -> 7.9 | J18: =I18-$C$16 -> 0.05375 | K18: =J18^2 -> 0.0028890625
A19: Source | B19: SS | C19: df | D19: MS | E19: F | F19: p-value | H19: =[1]Dataset!C226 -> Asia Pacific | I19: =Dataset!J31 -> 6.1 | J19: =I19-$C$16 -> -1.74625 | K19: =J19^2 -> 3.0493891
A20: Between regions | B20: =SUMPRODUCT(B10:B14,(C10:C14-$C$16)^2) -> 2.6008235 | C20: =4 -> 4 | D20: =B20/C20 -> 0.65020588 | E20: =D20/D21 -> 0.58125883 | F20: =FDIST(E20,C20,C21) -> 0.6771224 | H20: =[1]Dataset!C9 -> Europe | I20: =Dataset!J32 -> 8.6 | J20: =I20-$C$16 -> 0.75375 | K20: =J20^2 -> 0.56813906
A21: Within regions | B21: =K84 -> 85.014875 | C21: =B16-C20 -> 76 | D21: =B21/C21 -> 1.1186168 | H21: =[1]Dataset!C11 -> Europe | I21: =Dataset!J33 -> 8.6 | J21: =I21-$C$16 -> 0.75375 | K21: =J21^2 -> 0.56813906
A22: Total | B22: =B20+B21 -> 87.615699 | C22: =C20+C21 -> 80 | H22: =[1]Dataset!C12 -> Europe | I22: =Dataset!J34 -> 6.2 | J22: =I22-$C$16 -> -1.64625 | K22: =J22^2 -> 2.7101391
H23: =[1]Dataset!C39 -> Europe | I23: =Dataset!J35 -> 9.4 | J23: =I23-$C$16 -> 1.55375 | K23: =J23^2 -> 2.4141391
H24: =[1]Dataset!C40 -> Europe | I24: =Dataset!J36 -> 7.9 | J24: =I24-$C$16 -> 0.05375 | K24: =J24^2 -> 0.0028890625
A25: How the test works | H25: =[1]Dataset!C69 -> Europe | I25: =Dataset!J37 -> 6.2 | J25: =I25-$C$16 -> -1.64625 | K25: =J25^2 -> 2.7101391
A26: 1. First, we found the average Enterprise satisfaction for each region. | H26: =[1]Dataset!C70 -> Europe | I26: =Dataset!J38 -> 7.4 | J26: =I26-$C$16 -> -0.44625 | K26: =J26^2 -> 0.19913906
A27: 2. Then, we found the overall average for all Enterprise customers. | H27: =[1]Dataset!C99 -> Europe | I27: =Dataset!J39 -> 9.3 | J27: =I27-$C$16 -> 1.45375 | K27: =J27^2 -> 2.1133891
A28: 3. Next, we compared the five regional averages with the overall average. | H28: =[1]Dataset!C101 -> Europe | I28: =Dataset!J40 -> 8.3 | J28: =I28-$C$16 -> 0.45375 | K28: =J28^2 -> 0.20588906
A29: 4. We used ANOVA to check whether these differences are statistically significant. | H29: =[1]Dataset!C131 -> Europe | I29: =Dataset!J41 -> 7 | J29: =I29-$C$16 -> -0.84625 | K29: =J29^2 -> 0.71613906
A30: 5. Finally, we compared the p-value with 0.05 to make the decision. | H30: =[1]Dataset!C160 -> Europe | I30: =Dataset!J42 -> 9.1 | J30: =I30-$C$16 -> 1.25375 | K30: =J30^2 -> 1.5718891
H31: =[1]Dataset!C161 -> Europe | I31: =Dataset!J43 -> 8.1 | J31: =I31-$C$16 -> 0.25375 | K31: =J31^2 -> 0.064389063
A32: Conclusion | H32: =[1]Dataset!C188 -> Europe | I32: =Dataset!J44 -> 9.2 | J32: =I32-$C$16 -> 1.35375 | K32: =J32^2 -> 1.8326391
A33: Decision | B33: Fail to reject H0 | H33: =[1]Dataset!C190 -> Europe | I33: =Dataset!J45 -> 8.7 | J33: =I33-$C$16 -> 0.85375 | K33: =J33^2 -> 0.72888906
A34: Interpretation | B34: The regional averages are a little different, but the difference is not statistically significant at the 5% level (p = 0.651). | H34: =[1]Dataset!C191 -> Europe | I34: =Dataset!J46 -> 6.3 | J34: =I34-$C$16 -> -1.54625 | K34: =J34^2 -> 2.3908891
A35: Management action | B35: So, we would not give one region special attention based only on this test. We would keep watching the lower scores and check the actual customer issues behind them. | H35: =[1]Dataset!C218 -> Europe | I35: =Dataset!J47 -> 6.4 | J35: =I35-$C$16 -> -1.44625 | K35: =J35^2 -> 2.0916391
H36: =[1]Dataset!C221 -> Europe | I36: =Dataset!J48 -> 8.7 | J36: =I36-$C$16 -> 0.85375 | K36: =J36^2 -> 0.72888906
H37: =[1]Dataset!C23 -> Latin America | I37: =Dataset!J49 -> 6.6 | J37: =I37-$C$16 -> -1.24625 | K37: =J37^2 -> 1.5531391
H38: =[1]Dataset!C24 -> Latin America | I38: =Dataset!J50 -> 8.3 | J38: =I38-$C$16 -> 0.45375 | K38: =J38^2 -> 0.20588906
H39: =[1]Dataset!C50 -> Latin America | I39: =Dataset!J51 -> 9 | J39: =I39-$C$16 -> 1.15375 | K39: =J39^2 -> 1.3311391
H40: =[1]Dataset!C51 -> Latin America | I40: =Dataset!J52 -> 8.3 | J40: =I40-$C$16 -> 0.45375 | K40: =J40^2 -> 0.20588906
H41: =[1]Dataset!C80 -> Latin America | I41: =Dataset!J53 -> 8.2 | J41: =I41-$C$16 -> 0.35375 | K41: =J41^2 -> 0.12513906
...

Sheet Deliverable 3
A1: Deliverable 3 - Correlation
A3: Business question | B3: What factors are related to Revenue?
A4: Variable | B4: Role | C4: Why use it?
A5: Revenue | B5: Y (dependent) | C5: Revenue is the result we want to understand.
A6: Units Sold | B6: X candidate | C6: Units Sold can affect Revenue because selling more units can increase sales.
A7: Operating Cost | B7: X candidate | C7: Operating Cost shows the scale of business activity and may move with Revenue.
A9: Correlation results
A10: X variable | B10: Y variable | C10: Correlation (r) | D10: Simple reading
A11: Units Sold | B11: Revenue | C11: =CORREL([1]Dataset!$G$3:$G$241,[1]Dataset!$H$3:$H$241) -> 0.67369198 | D11: Revenue and Units Sold move in the same direction. The relationship is fairly strong.
A12: Operating Cost | B12: Revenue | C12: =CORREL([1]Dataset!$I$3:$I$241,[1]Dataset!$H$3:$H$241) -> 0.95929987 | D12: Revenue and Operating Cost move very closely together.
A14: How we did the calculation
A15: 1. First, we took Revenue as Y because it is the result we want to understand.
A16: 2. Then, we chose Units Sold and Operating Cost as possible X variables.
A17: 3. We used the CORREL formula to find how closely each X variable is related to Revenue.
A18: 4. A positive value means the two variables tend to increase together. A value closer to +1 means a stronger relationship.
A20: Interpretation | B20: Revenue has a positive relationship with both Units Sold and Operating Cost. The relationship with Operating Cost is much stronger (0.959) than with Units Sold (0.673).
B21: Management should keep an eye on operating costs. The strong relationship with Revenue is useful, but higher costs should be supported by enough additional revenue.
A26: The scatter plot shows a positive relationship between Units Sold and Revenue. As units sold increase, revenue generally increases. This is consistent with the correlation value of 0.674, which indicates a moderately strong positive relationship.
